<?xml version="1.0"?>
<robot name="air_quality_bot">

  <!-- Base Link -->
  <link name="base_link">
    <visual>
      <geometry>
        <box size="0.4 0.3 0.1"/>
      </geometry>
      <material name="blue">
        <color rgba="0 0 1 1"/>
      </material>
    </visual>
    <collision>
      <geometry>
        <box size="0.4 0.3 0.1"/>
      </geometry>
    </collision>
    <inertial>
      <mass value="5.0"/>
      <inertia ixx="0.1" ixy="0.0" ixz="0.0"
               iyy="0.1" iyz="0.0"
               izz="0.1"/>
      <origin xyz="0 0 0" rpy="0 0 0"/>
    </inertial>
  </link>

  <!-- Wheels -->
  <link name="wheel_front_left">
    <visual>
      <geometry>
        <cylinder radius="0.05" length="0.02"/>
      </geometry>
      <material name="black">
        <color rgba="0 0 0 1"/>
      </material>
    </visual>
  </link>
  <link name="wheel_front_right"/>
  <link name="wheel_back_left"/>
  <link name="wheel_back_right"/>

  <!-- Joints for wheels -->
  <joint name="joint_front_left_wheel" type="continuous">
    <parent link="base_link"/>
    <child link="wheel_front_left"/>
    <origin xyz="0.15 0.1 0" rpy="0 0 0"/>
    <axis xyz="0 1 0"/>
  </joint>
  <joint name="joint_front_right_wheel" type="continuous">
    <parent link="base_link"/>
    <child link="wheel_front_right"/>
    <origin xyz="0.15 -0.1 0" rpy="0 0 0"/>
    <axis xyz="0 1 0"/>
  </joint>
  <joint name="joint_back_left_wheel" type="continuous">
    <parent link="base_link"/>
    <child link="wheel_back_left"/>
    <origin xyz="-0.15 0.1 0" rpy="0 0 0"/>
    <axis xyz="0 1 0"/>
  </joint>
  <joint name="joint_back_right_wheel" type="continuous">
    <parent link="base_link"/>
    <child link="wheel_back_right"/>
    <origin xyz="-0.15 -0.1 0" rpy="0 0 0"/>
    <axis xyz="0 1 0"/>
  </joint>

  <!-- Sensor Mast -->
  <link name="sensor_mast">
    <visual>
      <geometry>
        <cylinder radius="0.02" length="0.5"/>
      </geometry>
      <material name="grey">
        <color rgba="0.5 0.5 0.5 1"/>
      </material>
    </visual>
  </link>

  <joint name="joint_sensor_mast" type="fixed">
    <parent link="base_link"/>
    <child link="sensor_mast"/>
    <origin xyz="0 0 0.05" rpy="0 0 0"/>
  </joint>

  <!-- Air Quality Sensor -->
  <link name="air_sensor">
    <visual>
      <geometry>
        <box size="0.05 0.05 0.05"/>
      </geometry>
      <material name="red">
        <color rgba="1 0 0 1"/>
      </material>
    </visual>
  </link>

  <joint name="joint_air_sensor" type="fixed">
    <parent link="sensor_mast"/>
    <child link="air_sensor"/>
    <origin xyz="0 0 0.25" rpy="0 0 0"/>
  </joint>

</robot>
